Workbook

Sheet Data Used - 1
A1: Post ID | B1: Platform | C1: Date | D1: Content Type | E1: Post Text | F1: Likes | G1: Shares | H1: Comments | I1: Impressions | J1: Reach | K1: Clicks | L1: Hashtags Used | M1: Hashtags Used 2 | N1: Hashtags Used 3 | O1: Hashtag Presence | P1: Campaign_Name | Q1: Engagement Rate
A2: P001 | B2: Twitter | C2: 2024-12-23 | D2: Reel | E2: Check out our latest reel on twitter! | F2: 1461 | G2: 184 | H2: 344 | I2: 21915 | J2: 21675 | K2: 15 | L2: #LiveForNow | M2: #AnytimeIsPepsiTime | P2: SummerSplash | Q2: =(F2+G2+H2)/I2 -> 0.090759754
A3: P002 | B3: Twitter | C3: 2025-04-03 | D3: Text | E3: Check out our latest text on twitter! | F3: 4054 | G3: 389 | H3: 493 | I3: 64864 | J3: 64383 | K3: 117 | L3: #PepsiCoRefresh | M3: #BetterWithPepsi | P3: FestiveRadiance | Q3: =(F3+G3+H3)/I3 -> 0.076097681
A4: P003 | B4: YouTube | C4: 2025-05-12 | D4: Reel | E4: Check out our latest reel on youtube! | F4: 2795 | G4: 105 | H4: 49 | I4: 53105 | J4: 52307 | K4: 204 | L4: #PepsiCoRefresh | P4: NewYearRefresh | Q4: =(F4+G4+H4)/I4 -> 0.055531494
A5: P004 | B5: Instagram | C5: 2024-08-12 | D5: Story | E5: Check out our latest story on instagram! | F5: 2404 | G5: 363 | H5: 138 | I5: 19232 | J5: 18636 | K5: 128 | L5: #ThirstyForMore | P5: DailyWellness | Q5: =(F5+G5+H5)/I5 -> 0.15105033
A6: P005 | B6: YouTube | C6: 2024-06-26 | D6: Reel | E6: Check out our latest reel on youtube! | F6: 3557 | G6: 687 | H6: 424 | I6: 71140 | J6: 70701 | K6: 224 | L6: #ThirstyForMore | M6: #PepsiCoRefresh | P6: SummerSplash | Q6: =(F6+G6+H6)/I6 -> 0.065617093
A7: P006 | B7: Facebook | C7: 2024-10-31 | D7: Carousel | E7: Check out our latest carousel on facebook! | F7: 2945 | G7: 930 | H7: 355 | I7: 23560 | J7: 23275 | K7: 256 | L7: #PepsiCoRefresh | P7: FestiveRadiance | Q7: =(F7+G7+H7)/I7 -> 0.1795416
A8: P007 | B8: Twitter | C8: 2024-06-24 | D8: Carousel | E8: Check out our latest carousel on twitter! | F8: 3860 | G8: 201 | H8: 279 | I8: 61760 | J8: 61660 | K8: 235 | L8: #PepsiCoRefresh | P8: FestiveRadiance | Q8: =(F8+G8+H8)/I8 -> 0.070272021
A9: P008 | B9: YouTube | C9: 2024-07-13 | D9: Image | E9: Check out our latest image on youtube! | F9: 3929 | G9: 262 | H9: 278 | I9: 43219 | J9: 42841 | K9: 39 | L9: #ThirstyForMore | P9: DailyWellness | Q9: =(F9+G9+H9)/I9 -> 0.1034036
A10: P009 | B10: Facebook | C10: 2024-08-30 | D10: Text | E10: Check out our latest text on facebook! | F10: 3784 | G10: 808 | H10: 404 | I10: 56760 | J10: 56343 | K10: 131 | L10: #PepsiCoRefresh | P10: FestiveRadiance | Q10: =(F10+G10+H10)/I10 -> 0.088019732
A11: P010 | B11: Facebook | C11: 2025-03-11 | D11: Image | E11: Check out our latest image on facebook! | F11: 4241 | G11: 902 | H11: 47 | I11: 72097 | J11: 71598 | K11: 167 | L11: #PepsiCoRefresh | P11: FestiveRadiance | Q11: =(F11+G11+H11)/I11 -> 0.071986352
A12: P011 | B12: Instagram | C12: 2025-02-02 | D12: Story | E12: Check out our latest story on instagram! | F12: 1792 | G12: 614 | H12: 497 | I12: 25088 | J12: 24675 | K12: 65 | L12: #LiveForNow | P12: DailyWellness | Q12: =(F12+G12+H12)/I12 -> 0.11571269
A13: P012 | B13: Facebook | C13: 2024-07-21 | D13: Reel | E13: Check out our latest reel on facebook! | F13: 1946 | G13: 686 | H13: 377 | I13: 23352 | J13: 22982 | K13: 213 | L13: #LiveForNow | P13: NewYearRefresh | Q13: =(F13+G13+H13)/I13 -> 0.12885406
A14: P013 | B14: YouTube | C14: 2024-11-18 | D14: Carousel | E14: Check out our latest carousel on youtube! | F14: 1171 | G14: 286 | H14: 231 | I14: 22249 | J14: 21282 | K14: 114 | L14: #ThirstyForMore | P14: SummerSplash | Q14: =(F14+G14+H14)/I14 -> 0.075868578
A15: P014 | B15: Facebook | C15: 2025-02-16 | D15: Story | E15: Check out our latest story on facebook! | F15: 4242 | G15: 555 | H15: 131 | I15: 33936 | J15: 33802 | K15: 265 | L15: #LiveForNow | Q15: =(F15+G15+H15)/I15 -> 0.14521452
A16: P015 | B16: Facebook | C16: 2024-10-24 | D16: Video | E16: Check out our latest video on facebook! | F16: 3888 | G16: 604 | H16: 128 | I16: 77760 | J16: 77167 | K16: 20 | L16: #LiveForNow | P16: SummerSplash | Q16: =(F16+G16+H16)/I16 -> 0.05941358
A17: P016 | B17: Facebook | C17: 2024-08-26 | D17: Text | E17: Check out our latest text on facebook! | F17: 3452 | G17: 377 | H17: 360 | I17: 55232 | J17: 55075 | K17: 87 | L17: #LiveForNow | P17: NewYearRefresh | Q17: =(F17+G17+H17)/I17 -> 0.075843714
A18: P017 | B18: Facebook | C18: 2025-05-05 | D18: Text | E18: Check out our latest text on facebook! | F18: 4441 | G18: 511 | H18: 70 | I18: 53292 | J18: 53082 | K18: 159 | L18: #ThirstyForMore | P18: DailyWellness | Q18: =(F18+G18+H18)/I18 -> 0.094235533
A19: P018 | B19: Instagram | C19: 2024-08-19 | D19: Reel | E19: Check out our latest reel on instagram! | F19: 3000 | G19: 382 | H19: 325 | I19: 36000 | J19: 35819 | K19: 19 | L19: #LiveForNow | P19: SummerSplash | Q19: =(F19+G19+H19)/I19 -> 0.10297222
A20: P019 | B20: Instagram | C20: 2024-06-23 | D20: Video | E20: Check out our latest video on instagram! | F20: 1071 | G20: 519 | H20: 22 | I20: 16065 | J20: 15865 | K20: 103 | L20: #PepsiCoRefresh | P20: DailyWellness | Q20: =(F20+G20+H20)/I20 -> 0.10034236
A21: P020 | B21: Instagram | C21: 2024-09-09 | D21: Carousel | E21: Check out our latest carousel on instagram! | F21: 4054 | G21: 488 | H21: 373 | I21: 77026 | J21: 76881 | K21: 25 | L21: #PepsiCoRefresh | P21: SummerSplash | Q21: =(F21+G21+H21)/I21 -> 0.063809623
A22: P021 | B22: Instagram | C22: 2025-01-04 | D22: Reel | E22: Check out our latest reel on instagram! | F22: 4838 | G22: 640 | H22: 128 | I22: 72570 | J22: 72396 | K22: 83 | L22: #LiveForNow | P22: DailyWellness | Q22: =(F22+G22+H22)/I22 -> 0.077249552
A23: P022 | B23: Facebook | C23: 2025-02-27 | D23: Text | E23: Check out our latest text on facebook! | F23: 1570 | G23: 187 | H23: 260 | I23: 25120 | J23: 24613 | K23: 133 | L23: #PepsiCoRefresh | P23: DailyWellness | Q23: =(F23+G23+H23)/I23 -> 0.080294586
A24: P023 | B24: Facebook | C24: 2024-11-06 | D24: Video | E24: Check out our latest video on facebook! | F24: 1606 | G24: 547 | H24: 316 | I24: 32120 | J24: 31736 | K24: 225 | L24: #PepsiCoRefresh | M24: #AnytimeIsPepsiTime | P24: FestiveRadiance | Q24: =(F24+G24+H24)/I24 -> 0.076867995
A25: P024 | B25: Facebook | C25: 2025-01-23 | D25: Video | E25: Check out our latest video on facebook! | F25: 3961 | G25: 761 | H25: 131 | I25: 67337 | J25: 66615 | K25: 161 | L25: #LiveForNow | P25: NewYearRefresh | Q25: =(F25+G25+H25)/I25 -> 0.072070333
A26: P025 | B26: Twitter | C26: 2025-04-10 | D26: Carousel | E26: Check out our latest carousel on twitter! | F26: 3128 | G26: 211 | H26: 197 | I26: 59432 | J26: 59182 | K26: 238 | L26: #ThirstyForMore | Q26: =(F26+G26+H26)/I26 -> 0.059496568
A27: P026 | B27: YouTube | C27: 2025-04-05 | D27: Reel | E27: Check out our latest reel on youtube! | F27: 3009 | G27: 413 | H27: 358 | I27: 42126 | J27: 41309 | K27: 211 | L27: #LiveForNow | P27: FestiveRadiance | Q27: =(F27+G27+H27)/I27 -> 0.089730808
A28: P027 | B28: YouTube | C28: 2024-09-17 | D28: Text | E28: Check out our latest text on youtube! | F28: 2076 | G28: 195 | H28: 104 | I28: 33216 | J28: 32244 | K28: 51 | L28: #LiveForNow | P28: DailyWellness | Q28: =(F28+G28+H28)/I28 -> 0.071501686
A29: P028 | B29: Instagram | C29: 2025-03-04 | D29: Video | E29: Check out our latest video on instagram! | F29: 432 | G29: 624 | H29: 123 | I29: 6912 | J29: 6259 | K29: 79 | L29: #LiveForNow | P29: DailyWellness | Q29: =(F29+G29+H29)/I29 -> 0.17057292
A30: P029 | B30: Instagram | C30: 2025-01-31 | D30: Carousel | E30: Check out our latest carousel on instagram! | F30: 2566 | G30: 118 | H30: 37 | I30: 12830 | J30: 12264 | K30: 221 | L30: #LiveForNow | P30: NewYearRefresh | Q30: =(F30+G30+H30)/I30 -> 0.21208106
A31: P030 | B31: Instagram | C31: 2025-02-25 | D31: Video | E31: Check out our latest video on instagram! | F31: 3095 | G31: 39 | H31: 78 | I31: 55710 | J31: 54808 | K31: 93 | L31: #ThirstyForMore | Q31: =(F31+G31+H31)/I31 -> 0.057655717
A32: P031 | B32: Instagram | C32: 2024-12-16 | D32: Text | E32: Check out our latest text on instagram! | F32: 438 | G32: 153 | H32: 275 | I32: 3066 | J32: 2701 | K32: 282 | L32: #PepsiCoRefresh | P32: FestiveRadiance | Q32: =(F32+G32+H32)/I32 -> 0.28245271
A33: P032 | B33: Twitter | C33: 2024-07-31 | D33: Carousel | E33: Check out our latest carousel on twitter! | F33: 2278 | G33: 10 | H33: 321 | I33: 13668 | J33: 12676 | K33: 275 | L33: #ThirstyForMore | P33: SummerSplash | Q33: =(F33+G33+H33)/I33 -> 0.19088382
A34: P033 | B34: Facebook | C34: 2024-08-21 | D34: Image | E34: Check out our latest image on facebook! | F34: 1407 | G34: 400 | H34: 351 | I34: 16884 | J34: 15954 | K34: 113 | L34: #PepsiCoRefresh | P34: SummerSplash | Q34: =(F34+G34+H34)/I34 -> 0.12781331
A35: P034 | B35: Facebook | C35: 2025-03-26 | D35: Text | E35: Check out our latest text on facebook! | F35: 1652 | G35: 89 | H35: 357 | I35: 29736 | J35: 28771 | K35: 215 | L35: #PepsiCoRefresh | P35: NewYearRefresh | Q35: =(F35+G35+H35)/I35 -> 0.07055421
A36: P035 | B36: Instagram | C36: 2024-11-30 | D36: Video | E36: Check out our latest video on instagram! | F36: 3775 | G36: 16 | H36: 239 | I36: 33975 | J36: 33310 | K36: 271 | L36: #LiveForNow | P36: FestiveRadiance | Q36: =(F36+G36+H36)/I36 -> 0.11861663
A37: P036 | B37: Instagram | C37: 2025-04-19 | D37: Story | E37: Check out our latest story on instagram! | F37: 4518 | G37: 285 | H37: 383 | I37: 67770 | J37: 67621 | K37: 31 | L37: #ThirstyForMore | P37: FestiveRadiance | Q37: =(F37+G37+H37)/I37 -> 0.076523535
A38: P037 | B38: Facebook | C38: 2025-01-06 | D38: Carousel | E38: Check out our latest carousel on facebook! | F38: 3024 | G38: 925 | H38: 350 | I38: 24192 | J38: 23518 | K38: 36 | L38: #ThirstyForMore | P38: FestiveRadiance | Q38: =(F38+G38+H38)/I38 -> 0.17770337
A39: P038 | B39: YouTube | C39: 2025-02-17 | D39: Reel | E39: Check out our latest reel on youtube! | F39: 3138 | G39: 123 | H39: 291 | I39: 28242 | J39: 27550 | K39: 87 | L39: #PepsiCoRefresh | P39: DailyWellness | Q39: =(F39+G39+H39)/I39 -> 0.12577013
A40: P039 | B40: Facebook | C40: 2024-11-25 | D40: Image | E40: Check out our latest image on facebook! | F40: 3564 | G40: 629 | H40: 177 | I40: 60588 | J40: 59627 | K40: 92 | L40: #PepsiCoRefresh | Q40: =(F40+G40+H40)/I40 -> 0.072126494
...

Sheet Performance for Hashtags
A1: Hashtags Used | B1: Average Performance | C1: Performance | D1: AVG likes | E1: Avg_Comments | F1: Count | G1: Sum 1 | H1: Sum 2 | I1: Sum 3 | J1: Comments Sum 1 | K1: Comments Sum 2 | L1: Comments Sum 3
A2: #LiveForNow | B2: =C2/F2 -> 2897.2233 | C2: =D2+E2 -> 298414 | D2: 271376 | E2: 27038 | F2: =COUNTIF('Data Used - 1'!L:L,A2)+COUNTIF('Data Used - 1'!M:M,A2)+COUNTIF('Data Used - 1'!N:N,A2) -> 103 | G2: =SUMIF('Data Used - 1'!L:L,A2,'Data Used - 1'!F:F) -> 271376 | H2: =SUMIF('Data Used - 1'!M:M,A2,'Data Used - 1'!F:F) -> 0 | I2: =SUMIF('Data Used - 1'!N:N,A2,'Data Used - 1'!F:F) -> 0 | J2: =SUMIF('Data Used - 1'!L:L,A2,'Data Used - 1'!H:H) -> 27038 | K2: =SUMIF('Data Used - 1'!M:M,A2,'Data Used - 1'!H:H) -> 0 | L2: =SUMIF('Data Used - 1'!N:N,A2,'Data Used - 1'!H:H) -> 0
A3: #PepsiCoRefresh | B3: =C3/F3 -> 1479.6449 | C3: =D3+E3 -> 158322 | D3: =(G3+H3)/2 -> 144723 | E3: =(J3+K3)/2 -> 13599 | F3: =COUNTIF('Data Used - 1'!L:L,A3)+COUNTIF('Data Used - 1'!M:M,A3)+COUNTIF('Data Used - 1'!N:N,A3) -> 107 | G3: =SUMIF('Data Used - 1'!L:L,A3,'Data Used - 1'!F:F) -> 276190 | H3: =SUMIF('Data Used - 1'!M:M,A3,'Data Used - 1'!F:F) -> 13256 | I3: =SUMIF('Data Used - 1'!N:N,A3,'Data Used - 1'!F:F) -> 0 | J3: =SUMIF('Data Used - 1'!L:L,A3,'Data Used - 1'!H:H) -> 25043 | K3: =SUMIF('Data Used - 1'!M:M,A3,'Data Used - 1'!H:H) -> 2155 | L3: =SUMIF('Data Used - 1'!N:N,A3,'Data Used - 1'!H:H) -> 0
A4: #ThirstyForMore | B4: =C4/F4 -> 1023.2516 | C4: =D4+E4 -> 104371.67 | D4: =(G4+H4+I4)/3 -> 96519.333 | E4: =(J4+K4+L4)/3 -> 7852.3333 | F4: =COUNTIF('Data Used - 1'!L:L,A4)+COUNTIF('Data Used - 1'!M:M,A4)+COUNTIF('Data Used - 1'!N:N,A4) -> 102 | G4: =SUMIF('Data Used - 1'!L:L,A4,'Data Used - 1'!F:F) -> 272425 | H4: =SUMIF('Data Used - 1'!M:M,A4,'Data Used - 1'!F:F) -> 15876 | I4: =SUMIF('Data Used - 1'!N:N,A4,'Data Used - 1'!F:F) -> 1257 | J4: =SUMIF('Data Used - 1'!L:L,A4,'Data Used - 1'!H:H) -> 22770 | K4: =SUMIF('Data Used - 1'!M:M,A4,'Data Used - 1'!H:H) -> 436 | L4: =SUMIF('Data Used - 1'!N:N,A4,'Data Used - 1'!H:H) -> 351
A5: #AnytimeIsPepsiTime | B5: =C5/F5 -> 1238.5 | C5: =D5+E5 -> 18577.5 | D5: =(H5+I5)/2 -> 16647 | E5: =(K5+L5)/2 -> 1930.5 | F5: =COUNTIF('Data Used - 1'!L:L,A5)+COUNTIF('Data Used - 1'!M:M,A5)+COUNTIF('Data Used - 1'!N:N,A5) -> 15 | G5: =SUMIF('Data Used - 1'!L:L,A5,'Data Used - 1'!F:F) -> 0 | H5: =SUMIF('Data Used - 1'!M:M,A5,'Data Used - 1'!F:F) -> 23595 | I5: =SUMIF('Data Used - 1'!N:N,A5,'Data Used - 1'!F:F) -> 9699 | J5: =SUMIF('Data Used - 1'!L:L,A5,'Data Used - 1'!H:H) -> 0 | K5: =SUMIF('Data Used - 1'!M:M,A5,'Data Used - 1'!H:H) -> 2130 | L5: =SUMIF('Data Used - 1'!N:N,A5,'Data Used - 1'!H:H) -> 1731
A6: #SmoothLikeNitroPepsi | B6: =C6/F6 -> 3411.2 | C6: =D6+E6 -> 17056 | D6: 15639 | E6: 1417 | F6: =COUNTIF('Data Used - 1'!L:L,A6)+COUNTIF('Data Used - 1'!M:M,A6)+COUNTIF('Data Used - 1'!N:N,A6) -> 5 | G6: =SUMIF('Data Used - 1'!L:L,A6,'Data Used - 1'!F:F) -> 0 | H6: =SUMIF('Data Used - 1'!M:M,A6,'Data Used - 1'!F:F) -> 15639 | I6: =SUMIF('Data Used - 1'!N:N,A6,'Data Used - 1'!F:F) -> 0 | J6: =SUMIF('Data Used - 1'!L:L,A6,'Data Used - 1'!H:H) -> 0 | K6: =SUMIF('Data Used - 1'!M:M,A6,'Data Used - 1'!H:H) -> 1417 | L6: =SUMIF('Data Used - 1'!N:N,A6,'Data Used - 1'!H:H) -> 0
A7: #BetterWithPepsi | B7: =C7/F7 -> 1801.3571 | C7: =D7+E7 -> 12609.5 | D7: =(H7+I7)/2 -> 12081 | E7: =(K7+L7)/2 -> 528.5 | F7: =COUNTIF('Data Used - 1'!L:L,A7)+COUNTIF('Data Used - 1'!M:M,A7)+COUNTIF('Data Used - 1'!N:N,A7) -> 7 | G7: =SUMIF('Data Used - 1'!L:L,A7,'Data Used - 1'!F:F) -> 0 | H7: =SUMIF('Data Used - 1'!M:M,A7,'Data Used - 1'!F:F) -> 8286 | I7: =SUMIF('Data Used - 1'!N:N,A7,'Data Used - 1'!F:F) -> 15876 | J7: =SUMIF('Data Used - 1'!L:L,A7,'Data Used - 1'!H:H) -> 0 | K7: =SUMIF('Data Used - 1'!M:M,A7,'Data Used - 1'!H:H) -> 621 | L7: =SUMIF('Data Used - 1'!N:N,A7,'Data Used - 1'!H:H) -> 436

Sheet Comparision Performance Content
A3: Average of Performance | B3: Content Type
A4: Platform | B4: Carousel | C4: Image | D4: Video | E4: Grand Total
A5: Facebook | B5: 0.12725513 | C5: 0.16666321 | D5: 0.15233235 | E5: 0.15266613
A6: Instagram | B6: 0.15327942 | C6: 0.13514319 | D6: 0.12301972 | E6: 0.13647501
A7: Twitter | B7: 1.115148 | C7: 0.19384066 | D7: 0.2529811 | E7: 0.62719534
A8: YouTube | B8: 0.22199844 | C8: 0.10407777 | D8: 0.14709031 | E8: 0.16215502
A9: Grand Total | B9: 0.51946121 | C9: 0.15755126 | D9: 0.16139418 | E9: 0.28796297

Sheet Conetnt Performance
A1: Post ID | B1: Platform | C1: Content Type | D1: Engagement Rate | E1: Click Rate | F1: Performance
A2: P062 | B2: Twitter | C2: Carousel | D2: =('Data Used - 1'!F63+'Data Used - 1'!G63+'Data Used - 1'!H63)/'Data Used - 1'!I63 -> 0.53773585 | E2: ='Data Used - 1'!K63/'Data Used - 1'!J63 -> 21.142857 | F2: =D2+E2 -> 21.680593
A3: P220 | B3: Twitter | C3: Story | D3: =('Data Used - 1'!F221+'Data Used - 1'!G221+'Data Used - 1'!H221)/'Data Used - 1'!I221 -> 1.8129252 | E3: ='Data Used - 1'!K221/'Data Used - 1'!J221 -> 1.5 | F3: =D3+E3 -> 3.3129252
A4: P058 | B4: Instagram | C4: Reel | D4: =('Data Used - 1'!F59+'Data Used - 1'!G59+'Data Used - 1'!H59)/'Data Used - 1'!I59 -> 0.86601942 | E4: ='Data Used - 1'!K59/'Data Used - 1'!J59 -> 0.63902439 | F4: =D4+E4 -> 1.5050438
A5: P264 | B5: Twitter | C5: Image | D5: =('Data Used - 1'!F265+'Data Used - 1'!G265+'Data Used - 1'!H265)/'Data Used - 1'!I265 -> 0.53389831 | E5: ='Data Used - 1'!K265/'Data Used - 1'!J265 -> 0.61684211 | F5: =D5+E5 -> 1.1507404
A6: P178 | B6: Twitter | C6: Video | D6: =('Data Used - 1'!F179+'Data Used - 1'!G179+'Data Used - 1'!H179)/'Data Used - 1'!I179 -> 0.70387597 | E6: ='Data Used - 1'!K179/'Data Used - 1'!J179 -> 0.28367104 | F6: =D6+E6 -> 0.98754701
A7: P232 | B7: Facebook | C7: Story | D7: =('Data Used - 1'!F233+'Data Used - 1'!G233+'Data Used - 1'!H233)/'Data Used - 1'!I233 -> 0.71686747 | E7: ='Data Used - 1'!K233/'Data Used - 1'!J233 -> 0.19252874 | F7: =D7+E7 -> 0.90939621
A8: P143 | B8: YouTube | C8: Carousel | D8: =('Data Used - 1'!F144+'Data Used - 1'!G144+'Data Used - 1'!H144)/'Data Used - 1'!I144 -> 0.50192308 | E8: ='Data Used - 1'!K144/'Data Used - 1'!J144 -> 0.33524355 | F8: =D8+E8 -> 0.83716663
A9: P175 | B9: Instagram | C9: Reel | D9: =('Data Used - 1'!F176+'Data Used - 1'!G176+'Data Used - 1'!H176)/'Data Used - 1'!I176 -> 0.6508216 | E9: ='Data Used - 1'!K176/'Data Used - 1'!J176 -> 0.15477387 | F9: =D9+E9 -> 0.80559547
A10: P210 | B10: Twitter | C10: Image | D10: =('Data Used - 1'!F211+'Data Used - 1'!G211+'Data Used - 1'!H211)/'Data Used - 1'!I211 -> 0.48518408 | E10: ='Data Used - 1'!K211/'Data Used - 1'!J211 -> 0.10424991 | F10: =D10+E10 -> 0.58943399
A11: P214 | B11: Facebook | C11: Image | D11: =('Data Used - 1'!F215+'Data Used - 1'!G215+'Data Used - 1'!H215)/'Data Used - 1'!I215 -> 0.37955854 | E11: ='Data Used - 1'!K215/'Data Used - 1'!J215 -> 0.082965578 | F11: =D11+E11 -> 0.46252412
A12: P102 | B12: Twitter | C12: Reel | D12: =('Data Used - 1'!F103+'Data Used - 1'!G103+'Data Used - 1'!H103)/'Data Used - 1'!I103 -> 0.35666667 | E12: ='Data Used - 1'!K103/'Data Used - 1'!J103 -> 0.042712124 | F12: =D12+E12 -> 0.39937879
A13: P070 | B13: Twitter | C13: Video | D13: =('Data Used - 1'!F71+'Data Used - 1'!G71+'Data Used - 1'!H71)/'Data Used - 1'!I71 -> 0.38274707 | E13: ='Data Used - 1'!K71/'Data Used - 1'!J71 -> 0.014390897 | F13: =D13+E13 -> 0.39713797
A14: P031 | B14: Twitter | C14: Text | D14: =('Data Used - 1'!F32+'Data Used - 1'!G32+'Data Used - 1'!H32)/'Data Used - 1'!I32 -> 0.28245271 | E14: ='Data Used - 1'!K32/'Data Used - 1'!J32 -> 0.10440578 | F14: =D14+E14 -> 0.38685848
A15: P053 | B15: Twitter | C15: Carousel | D15: =('Data Used - 1'!F54+'Data Used - 1'!G54+'Data Used - 1'!H54)/'Data Used - 1'!I54 -> 0.36965174 | E15: ='Data Used - 1'!K54/'Data Used - 1'!J54 -> 0.0034987277 | F15: =D15+E15 -> 0.37315047
A16: P066 | B16: Facebook | C16: Carousel | D16: =('Data Used - 1'!F67+'Data Used - 1'!G67+'Data Used - 1'!H67)/'Data Used - 1'!I67 -> 0.29199735 | E16: ='Data Used - 1'!K67/'Data Used - 1'!J67 -> 0.080525164 | F16: =D16+E16 -> 0.37252252
A17: P224 | B17: Facebook | C17: Image | D17: =('Data Used - 1'!F225+'Data Used - 1'!G225+'Data Used - 1'!H225)/'Data Used - 1'!I225 -> 0.32083531 | E17: ='Data Used - 1'!K225/'Data Used - 1'!J225 -> 0.048765983 | F17: =D17+E17 -> 0.36960129
A18: P121 | B18: Facebook | C18: Story | D18: =('Data Used - 1'!F122+'Data Used - 1'!G122+'Data Used - 1'!H122)/'Data Used - 1'!I122 -> 0.32349398 | E18: ='Data Used - 1'!K122/'Data Used - 1'!J122 -> 0.044205496 | F18: =D18+E18 -> 0.36769947
A19: P124 | B19: YouTube | C19: Carousel | D19: =('Data Used - 1'!F125+'Data Used - 1'!G125+'Data Used - 1'!H125)/'Data Used - 1'!I125 -> 0.33618012 | E19: ='Data Used - 1'!K125/'Data Used - 1'!J125 -> 0.0040373991 | F19: =D19+E19 -> 0.34021752
A20: P183 | B20: Twitter | C20: Story | D20: =('Data Used - 1'!F184+'Data Used - 1'!G184+'Data Used - 1'!H184)/'Data Used - 1'!I184 -> 0.28696581 | E20: ='Data Used - 1'!K184/'Data Used - 1'!J184 -> 0.048125868 | F20: =D20+E20 -> 0.33509168
A21: P119 | B21: Facebook | C21: Reel | D21: =('Data Used - 1'!F120+'Data Used - 1'!G120+'Data Used - 1'!H120)/'Data Used - 1'!I120 -> 0.31705584 | E21: ='Data Used - 1'!K120/'Data Used - 1'!J120 -> 0.013110713 | F21: =D21+E21 -> 0.33016655
A22: P154 | B22: Twitter | C22: Carousel | D22: =('Data Used - 1'!F155+'Data Used - 1'!G155+'Data Used - 1'!H155)/'Data Used - 1'!I155 -> 0.31965192 | E22: ='Data Used - 1'!K155/'Data Used - 1'!J155 -> 0.009471659 | F22: =D22+E22 -> 0.32912358
A23: P204 | B23: YouTube | C23: Carousel | D23: =('Data Used - 1'!F205+'Data Used - 1'!G205+'Data Used - 1'!H205)/'Data Used - 1'!I205 -> 0.29713518 | E23: ='Data Used - 1'!K205/'Data Used - 1'!J205 -> 0.018734033 | F23: =D23+E23 -> 0.31586922
A24: P248 | B24: Twitter | C24: Story | D24: =('Data Used - 1'!F249+'Data Used - 1'!G249+'Data Used - 1'!H249)/'Data Used - 1'!I249 -> 0.26297968 | E24: ='Data Used - 1'!K249/'Data Used - 1'!J249 -> 0.052514243 | F24: =D24+E24 -> 0.31549393
A25: P287 | B25: Facebook | C25: Reel | D25: =('Data Used - 1'!F288+'Data Used - 1'!G288+'Data Used - 1'!H288)/'Data Used - 1'!I288 -> 0.30126002 | E25: ='Data Used - 1'!K288/'Data Used - 1'!J288 -> 0.012356841 | F25: =D25+E25 -> 0.31361686
A26: P219 | B26: Twitter | C26: Reel | D26: =('Data Used - 1'!F220+'Data Used - 1'!G220+'Data Used - 1'!H220)/'Data Used - 1'!I220 -> 0.25701459 | E26: ='Data Used - 1'!K220/'Data Used - 1'!J220 -> 0.043938161 | F26: =D26+E26 -> 0.30095275
A27: P093 | B27: Instagram | C27: Video | D27: =('Data Used - 1'!F94+'Data Used - 1'!G94+'Data Used - 1'!H94)/'Data Used - 1'!I94 -> 0.28045656 | E27: ='Data Used - 1'!K94/'Data Used - 1'!J94 -> 0.01786565 | F27: =D27+E27 -> 0.29832221
A28: P259 | B28: Instagram | C28: Text | D28: =('Data Used - 1'!F260+'Data Used - 1'!G260+'Data Used - 1'!H260)/'Data Used - 1'!I260 -> 0.25771056 | E28: ='Data Used - 1'!K260/'Data Used - 1'!J260 -> 0.031632653 | F28: =D28+E28 -> 0.28934321
A29: P263 | B29: Facebook | C29: Reel | D29: =('Data Used - 1'!F264+'Data Used - 1'!G264+'Data Used - 1'!H264)/'Data Used - 1'!I264 -> 0.26876681 | E29: ='Data Used - 1'!K264/'Data Used - 1'!J264 -> 0.0016488046 | F29: =D29+E29 -> 0.27041561
A30: P226 | B30: Twitter | C30: Carousel | D30: =('Data Used - 1'!F227+'Data Used - 1'!G227+'Data Used - 1'!H227)/'Data Used - 1'!I227 -> 0.25537048 | E30: ='Data Used - 1'!K227/'Data Used - 1'!J227 -> 0.01462766 | F30: =D30+E30 -> 0.26999814
A31: P181 | B31: Facebook | C31: Image | D31: =('Data Used - 1'!F182+'Data Used - 1'!G182+'Data Used - 1'!H182)/'Data Used - 1'!I182 -> 0.23673521 | E31: ='Data Used - 1'!K182/'Data Used - 1'!J182 -> 0.032345378 | F31: =D31+E31 -> 0.26908059
A32: P246 | B32: Facebook | C32: Image | D32: =('Data Used - 1'!F247+'Data Used - 1'!G247+'Data Used - 1'!H247)/'Data Used - 1'!I247 -> 0.2365625 | E32: ='Data Used - 1'!K247/'Data Used - 1'!J247 -> 0.029239766 | F32: =D32+E32 -> 0.26580227
A33: P244 | B33: Facebook | C33: Video | D33: =('Data Used - 1'!F245+'Data Used - 1'!G245+'Data Used - 1'!H245)/'Data Used - 1'!I245 -> 0.25869985 | E33: ='Data Used - 1'!K245/'Data Used - 1'!J245 -> 0.0027897091 | F33: =D33+E33 -> 0.26148956
A34: P277 | B34: Facebook | C34: Image | D34: =('Data Used - 1'!F278+'Data Used - 1'!G278+'Data Used - 1'!H278)/'Data Used - 1'!I278 -> 0.24763928 | E34: ='Data Used - 1'!K278/'Data Used - 1'!J278 -> 0.011600702 | F34: =D34+E34 -> 0.25923998
A35: P265 | B35: Instagram | C35: Carousel | D35: =('Data Used - 1'!F266+'Data Used - 1'!G266+'Data Used - 1'!H266)/'Data Used - 1'!I266 -> 0.25279702 | E35: ='Data Used - 1'!K266/'Data Used - 1'!J266 -> 0.0037384882 | F35: =D35+E35 -> 0.2565355
A36: P239 | B36: Facebook | C36: Text | D36: =('Data Used - 1'!F240+'Data Used - 1'!G240+'Data Used - 1'!H240)/'Data Used - 1'!I240 -> 0.25062082 | E36: ='Data Used - 1'!K240/'Data Used - 1'!J240 -> 0.0049826584 | F36: =D36+E36 -> 0.25560348
A37: P297 | B37: YouTube | C37: Text | D37: =('Data Used - 1'!F298+'Data Used - 1'!G298+'Data Used - 1'!H298)/'Data Used - 1'!I298 -> 0.2434903 | E37: ='Data Used - 1'!K298/'Data Used - 1'!J298 -> 0.0023426061 | F37: =D37+E37 -> 0.24583291
A38: P120 | B38: Instagram | C38: Story | D38: =('Data Used - 1'!F121+'Data Used - 1'!G121+'Data Used - 1'!H121)/'Data Used - 1'!I121 -> 0.23414918 | E38: ='Data Used - 1'!K121/'Data Used - 1'!J121 -> 0.011260983 | F38: =D38+E38 -> 0.24541017
A39: P141 | B39: Instagram | C39: Image | D39: =('Data Used - 1'!F142+'Data Used - 1'!G142+'Data Used - 1'!H142)/'Data Used - 1'!I142 -> 0.23165089 | E39: ='Data Used - 1'!K142/'Data Used - 1'!J142 -> 0.012931731 | F39: =D39+E39 -> 0.24458263
A40: P123 | B40: Facebook | C40: Story | D40: =('Data Used - 1'!F124+'Data Used - 1'!G124+'Data Used - 1'!H124)/'Data Used - 1'!I124 -> 0.23616777 | E40: ='Data Used - 1'!K124/'Data Used - 1'!J124 -> 0.0073087845 | F40: =D40+E40 -> 0.24347656
...
