Workbook

Sheet Data Used -1
A1: Post ID | B1: Platform | C1: Date | D1: Content Type | E1: Post Text | F1: Likes | G1: Shares | H1: Comments | I1: Impressions | J1: Reach | K1: Clicks | L1: Hashtags Used | M1: Campaign_Name | N1: Engagement Rate
A2: P001 | B2: Twitter | C2: 2024-12-23 | D2: Reel | E2: Check out our latest reel on twitter! | F2: 1461 | G2: 184 | H2: 344 | I2: 21915 | J2: 21675 | K2: 15 | L2: #LiveForNow,#AnytimeIsPepsiTime | M2: SummerSplash
A3: P002 | B3: Twitter | C3: 2025-04-03 | D3: Text | E3: Check out our latest text on twitter! | F3: 4054 | G3: 389 | H3: 493 | I3: 64864 | J3: 64383 | K3: 117 | L3: #PepsiCoRefresh,#BetterWithPepsi | M3: FestiveRadiance
A4: P003 | B4: YouTube | C4: 2025-05-12 | D4: Reel | E4: Check out our latest reel on youtube! | F4: 2795 | G4: 105 | H4: 49 | I4: 53105 | J4: 52307 | K4: 204 | L4: #PepsiCoRefresh | M4: NewYearRefresh
A5: P004 | B5: Instagram | C5: 2024-08-12 | D5: Story | E5: Check out our latest story on instagram! | F5: 2404 | G5: 363 | H5: 138 | I5: 19232 | J5: 18636 | K5: 128 | L5: #ThirstyForMore | M5: DailyWellness
A6: P005 | B6: YouTube | C6: 2024-06-26 | D6: Reel | E6: Check out our latest reel on youtube! | F6: 3557 | G6: 687 | H6: 424 | I6: 71140 | J6: 70701 | K6: 224 | L6: #ThirstyForMore,#PepsiCoRefresh | M6: SummerSplash
A7: P006 | B7: Facebook | C7: 2024-10-31 | D7: Carousel | E7: Check out our latest carousel on facebook! | F7: 2945 | G7: 930 | H7: 355 | I7: 23560 | J7: 23275 | K7: 256 | L7: #PepsiCoRefresh | M7: FestiveRadiance
A8: P007 | B8: Twitter | C8: 2024-06-24 | D8: Carousel | E8: Check out our latest carousel on twitter! | F8: 3860 | G8: 201 | H8: 279 | I8: 61760 | J8: 61660 | K8: 235 | L8: #PepsiCoRefresh | M8: FestiveRadiance
A9: P008 | B9: YouTube | C9: 2024-07-13 | D9: Image | E9: Check out our latest image on youtube! | F9: 3929 | G9: 262 | H9: 278 | I9: 43219 | J9: 42841 | K9: 39 | L9: #ThirstyForMore | M9: DailyWellness
A10: P009 | B10: Facebook | C10: 2024-08-30 | D10: Text | E10: Check out our latest text on facebook! | F10: 3784 | G10: 808 | H10: 404 | I10: 56760 | J10: 56343 | K10: 131 | L10: #PepsiCoRefresh | M10: FestiveRadiance
A11: P010 | B11: Facebook | C11: 2025-03-11 | D11: Image | E11: Check out our latest image on facebook! | F11: 4241 | G11: 902 | H11: 47 | I11: 72097 | J11: 71598 | K11: 167 | L11: #PepsiCoRefresh | M11: FestiveRadiance
A12: P011 | B12: Instagram | C12: 2025-02-02 | D12: Story | E12: Check out our latest story on instagram! | F12: 1792 | G12: 614 | H12: 497 | I12: 25088 | J12: 24675 | K12: 65 | L12: #LiveForNow | M12: DailyWellness
A13: P012 | B13: Facebook | C13: 2024-07-21 | D13: Reel | E13: Check out our latest reel on facebook! | F13: 1946 | G13: 686 | H13: 377 | I13: 23352 | J13: 22982 | K13: 213 | L13: #LiveForNow | M13: NewYearRefresh
A14: P013 | B14: YouTube | C14: 2024-11-18 | D14: Carousel | E14: Check out our latest carousel on youtube! | F14: 1171 | G14: 286 | H14: 231 | I14: 22249 | J14: 21282 | K14: 114 | L14: #ThirstyForMore | M14: SummerSplash
A15: P014 | B15: Facebook | C15: 2025-02-16 | D15: Story | E15: Check out our latest story on facebook! | F15: 4242 | G15: 555 | H15: 131 | I15: 33936 | J15: 33802 | K15: 265 | L15: #LiveForNow
A16: P015 | B16: Facebook | C16: 2024-10-24 | D16: Video | E16: Check out our latest video on facebook! | F16: 3888 | G16: 604 | H16: 128 | I16: 77760 | J16: 77167 | K16: 20 | L16: #LiveForNow | M16: SummerSplash
A17: P016 | B17: Facebook | C17: 2024-08-26 | D17: Text | E17: Check out our latest text on facebook! | F17: 3452 | G17: 377 | H17: 360 | I17: 55232 | J17: 55075 | K17: 87 | L17: #LiveForNow | M17: NewYearRefresh
A18: P017 | B18: Facebook | C18: 2025-05-05 | D18: Text | E18: Check out our latest text on facebook! | F18: 4441 | G18: 511 | H18: 70 | I18: 53292 | J18: 53082 | K18: 159 | L18: #ThirstyForMore | M18: DailyWellness
A19: P018 | B19: Instagram | C19: 2024-08-19 | D19: Reel | E19: Check out our latest reel on instagram! | F19: 3000 | G19: 382 | H19: 325 | I19: 36000 | J19: 35819 | K19: 19 | L19: #LiveForNow | M19: SummerSplash
A20: P019 | B20: Instagram | C20: 2024-06-23 | D20: Video | E20: Check out our latest video on instagram! | F20: 1071 | G20: 519 | H20: 22 | I20: 16065 | J20: 15865 | K20: 103 | L20: #PepsiCoRefresh | M20: DailyWellness
A21: P020 | B21: Instagram | C21: 2024-09-09 | D21: Carousel | E21: Check out our latest carousel on instagram! | F21: 4054 | G21: 488 | H21: 373 | I21: 77026 | J21: 76881 | K21: 25 | L21: #PepsiCoRefresh | M21: SummerSplash
A22: P021 | B22: Instagram | C22: 2025-01-04 | D22: Reel | E22: Check out our latest reel on instagram! | F22: 4838 | G22: 640 | H22: 128 | I22: 72570 | J22: 72396 | K22: 83 | L22: #LiveForNow | M22: DailyWellness
A23: P022 | B23: Facebook | C23: 2025-02-27 | D23: Text | E23: Check out our latest text on facebook! | F23: 1570 | G23: 187 | H23: 260 | I23: 25120 | J23: 24613 | K23: 133 | L23: #PepsiCoRefresh | M23: DailyWellness
A24: P023 | B24: Facebook | C24: 2024-11-06 | D24: Video | E24: Check out our latest video on facebook! | F24: 1606 | G24: 547 | H24: 316 | I24: 32120 | J24: 31736 | K24: 225 | L24: #PepsiCoRefresh,#AnytimeIsPepsiTime | M24: FestiveRadiance
A25: P024 | B25: Facebook | C25: 2025-01-23 | D25: Video | E25: Check out our latest video on facebook! | F25: 3961 | G25: 761 | H25: 131 | I25: 67337 | J25: 66615 | K25: 161 | L25: #LiveForNow | M25: NewYearRefresh
A26: P025 | B26: Twitter | C26: 2025-04-10 | D26: Carousel | E26: Check out our latest carousel on twitter! | F26: 3128 | G26: 211 | H26: 197 | I26: 59432 | J26: 59182 | K26: 238 | L26: #ThirstyForMore
A27: P026 | B27: YouTube | C27: 2025-04-05 | D27: Reel | E27: Check out our latest reel on youtube! | F27: 3009 | G27: 413 | H27: 358 | I27: 42126 | J27: 41309 | K27: 211 | L27: #LiveForNow | M27: FestiveRadiance
A28: P027 | B28: YouTube | C28: 2024-09-17 | D28: Text | E28: Check out our latest text on youtube! | F28: 2076 | G28: 195 | H28: 104 | I28: 33216 | J28: 32244 | K28: 51 | L28: #LiveForNow | M28: DailyWellness
A29: P028 | B29: Instagram | C29: 2025-03-04 | D29: Video | E29: Check out our latest video on instagram! | F29: 432 | G29: 624 | H29: 123 | I29: 6912 | J29: 6259 | K29: 79 | L29: #LiveForNow | M29: DailyWellness
A30: P029 | B30: Instagram | C30: 2025-01-31 | D30: Carousel | E30: Check out our latest carousel on instagram! | F30: 2566 | G30: 118 | H30: 37 | I30: 12830 | J30: 12264 | K30: 221 | L30: #LiveForNow | M30: NewYearRefresh
A31: P030 | B31: Instagram | C31: 2025-02-25 | D31: Video | E31: Check out our latest video on instagram! | F31: 3095 | G31: 39 | H31: 78 | I31: 55710 | J31: 54808 | K31: 93 | L31: #ThirstyForMore
A32: P031 | B32: Instagram | C32: 2024-12-16 | D32: Text | E32: Check out our latest text on instagram! | F32: 438 | G32: 153 | H32: 275 | I32: 3066 | J32: 2701 | K32: 282 | L32: #PepsiCoRefresh | M32: FestiveRadiance
A33: P032 | B33: Twitter | C33: 2024-07-31 | D33: Carousel | E33: Check out our latest carousel on twitter! | F33: 2278 | G33: 10 | H33: 321 | I33: 13668 | J33: 12676 | K33: 275 | L33: #ThirstyForMore | M33: SummerSplash
A34: P033 | B34: Facebook | C34: 2024-08-21 | D34: Image | E34: Check out our latest image on facebook! | F34: 1407 | G34: 400 | H34: 351 | I34: 16884 | J34: 15954 | K34: 113 | L34: #PepsiCoRefresh | M34: SummerSplash
A35: P034 | B35: Facebook | C35: 2025-03-26 | D35: Text | E35: Check out our latest text on facebook! | F35: 1652 | G35: 89 | H35: 357 | I35: 29736 | J35: 28771 | K35: 215 | L35: #PepsiCoRefresh | M35: NewYearRefresh
A36: P035 | B36: Instagram | C36: 2024-11-30 | D36: Video | E36: Check out our latest video on instagram! | F36: 3775 | G36: 16 | H36: 239 | I36: 33975 | J36: 33310 | K36: 271 | L36: #LiveForNow | M36: FestiveRadiance
A37: P036 | B37: Instagram | C37: 2025-04-19 | D37: Story | E37: Check out our latest story on instagram! | F37: 4518 | G37: 285 | H37: 383 | I37: 67770 | J37: 67621 | K37: 31 | L37: #ThirstyForMore | M37: FestiveRadiance
A38: P037 | B38: Facebook | C38: 2025-01-06 | D38: Carousel | E38: Check out our latest carousel on facebook! | F38: 3024 | G38: 925 | H38: 350 | I38: 24192 | J38: 23518 | K38: 36 | L38: #ThirstyForMore | M38: FestiveRadiance
A39: P038 | B39: YouTube | C39: 2025-02-17 | D39: Reel | E39: Check out our latest reel on youtube! | F39: 3138 | G39: 123 | H39: 291 | I39: 28242 | J39: 27550 | K39: 87 | L39: #PepsiCoRefresh | M39: DailyWellness
A40: P039 | B40: Facebook | C40: 2024-11-25 | D40: Image | E40: Check out our latest image on facebook! | F40: 3564 | G40: 629 | H40: 177 | I40: 60588 | J40: 59627 | K40: 92 | L40: #PepsiCoRefresh
...

Sheet Data Used- 2
A1: Campaign_Name | B1: Start_Date | C1: End_Date | D1: Objective | E1: Total_Budget | F1: Target_Platforms | G1: Primary_Hashtags
A2: SummerSplash | B2: 2024-06-15 | C2: 2024-07-15 | D2: Brand Awareness | E2: 150000 | F2: Instagram,Facebook | G2: #ThirstyForMore,#PepsiCoRefresh
A3: FestiveRadiance | B3: 2024-10-01 | C3: 2024-10-31 | D3: Engagement | E3: 200000 | F3: Instagram,YouTube | G3: #AnytimeIsPepsiTime,
A4: NewYearRefresh | B4: 2024-12-25 | C4: 2025-01-10 | D4: Product Launch | E4: 250000 | F4: Facebook,Twitter | G4: #SmoothLikeNitroPepsi
A5: DailyWellness | B5: 2025-03-01 | C5: 2025-03-31 | D5: Traffic | E5: 180000 | F5: Instagram,Twitter | G5: #BetterWithPepsi,#LiveForNow

Sheet Data Used - 3
A1: Week_Start_Date | B1: Platform | C1: New_Followers | D1: Unfollows | E1: Total_Followers | F1: Engagement_Rate | G1: Ad_Spend | H1: SummerSplash Flag | I1: FestiveRadiance | J1: NewYearRefresh Flag | K1: DailyWellness Flag
A2: 2024-06-03 | B2: Instagram | C2: 1135 | D2: 88 | E2: 344084 | F2: 8.06 | G2: 5904 | H2: =IF(AND(A2 >= 'Task - Upliftment'!$E$2, A2 <= 'Task - Upliftment'!$F$2, OR(B2="Instagram", B2="Facebook")), "Present", IF(A2 < 'Task - Upliftment'!$E$2, IF(OR(B2="Instagram", B2="Facebook"), "Before", "NP"), "NP")) -> Before | I2: =IF(AND(A2 >= 'Task - Upliftment'!$E$3, A2 <= 'Task - Upliftment'!$F$3, OR(B2="Instagram", B2="YouTube")), "Present", IF(A2 < 'Task - Upliftment'!$E$3, IF(OR(B2="Instagram", B2="YouTube"), "Before", "NP"), "NP")) -> Before | J2: =IF(AND(A2 >= 'Task - Upliftment'!$E$4, A2 <= 'Task - Upliftment'!$F$4, OR(B2="Facebook", B2="Twitter")), "Present", IF(A2 < 'Task - Upliftment'!$E$4, IF(OR(B2="Facebook", B2="Twitter"), "Before", "NP"), "NP")) -> NP | K2: =IF(AND(A2 >= 'Task - Upliftment'!$E$5, A2 <= 'Task - Upliftment'!$F$5, OR(B2="Instagram", B2="Twitter")), "Present", IF(A2 < 'Task - Upliftment'!$E$5, IF(OR(B2="Instagram", B2="Twitter"), "Before", "NP"), "NP")) -> Before
A3: 2024-06-03 | B3: Facebook | C3: 1312 | D3: 310 | E3: 42654 | F3: 4.98 | G3: 9566 | H3: =IF(AND(A3 >= 'Task - Upliftment'!$E$2, A3 <= 'Task - Upliftment'!$F$2, OR(B3="Instagram", B3="Facebook")), "Present", IF(A3 < 'Task - Upliftment'!$E$2, IF(OR(B3="Instagram", B3="Facebook"), "Before", "NP"), "NP")) -> Before | I3: =IF(AND(A3 >= 'Task - Upliftment'!$E$3, A3 <= 'Task - Upliftment'!$F$3, OR(B3="Instagram", B3="YouTube")), "Present", IF(A3 < 'Task - Upliftment'!$E$3, IF(OR(B3="Instagram", B3="YouTube"), "Before", "NP"), "NP")) -> NP | J3: =IF(AND(A3 >= 'Task - Upliftment'!$E$4, A3 <= 'Task - Upliftment'!$F$4, OR(B3="Facebook", B3="Twitter")), "Present", IF(A3 < 'Task - Upliftment'!$E$4, IF(OR(B3="Facebook", B3="Twitter"), "Before", "NP"), "NP")) -> Before | K3: =IF(AND(A3 >= 'Task - Upliftment'!$E$5, A3 <= 'Task - Upliftment'!$F$5, OR(B3="Instagram", B3="Twitter")), "Present", IF(A3 < 'Task - Upliftment'!$E$5, IF(OR(B3="Instagram", B3="Twitter"), "Before", "NP"), "NP")) -> NP
A4: 2024-06-03 | B4: Twitter | C4: 584 | D4: 169 | E4: 146834 | F4: 8.31 | G4: 26752 | H4: =IF(AND(A4 >= 'Task - Upliftment'!$E$2, A4 <= 'Task - Upliftment'!$F$2, OR(B4="Instagram", B4="Facebook")), "Present", IF(A4 < 'Task - Upliftment'!$E$2, IF(OR(B4="Instagram", B4="Facebook"), "Before", "NP"), "NP")) -> NP | I4: =IF(AND(A4 >= 'Task - Upliftment'!$E$3, A4 <= 'Task - Upliftment'!$F$3, OR(B4="Instagram", B4="YouTube")), "Present", IF(A4 < 'Task - Upliftment'!$E$3, IF(OR(B4="Instagram", B4="YouTube"), "Before", "NP"), "NP")) -> NP | J4: =IF(AND(A4 >= 'Task - Upliftment'!$E$4, A4 <= 'Task - Upliftment'!$F$4, OR(B4="Facebook", B4="Twitter")), "Present", IF(A4 < 'Task - Upliftment'!$E$4, IF(OR(B4="Facebook", B4="Twitter"), "Before", "NP"), "NP")) -> Before | K4: =IF(AND(A4 >= 'Task - Upliftment'!$E$5, A4 <= 'Task - Upliftment'!$F$5, OR(B4="Instagram", B4="Twitter")), "Present", IF(A4 < 'Task - Upliftment'!$E$5, IF(OR(B4="Instagram", B4="Twitter"), "Before", "NP"), "NP")) -> Before
A5: 2024-06-03 | B5: YouTube | C5: 1535 | D5: 445 | E5: 395536 | F5: 4.11 | G5: 30671 | H5: =IF(AND(A5 >= 'Task - Upliftment'!$E$2, A5 <= 'Task - Upliftment'!$F$2, OR(B5="Instagram", B5="Facebook")), "Present", IF(A5 < 'Task - Upliftment'!$E$2, IF(OR(B5="Instagram", B5="Facebook"), "Before", "NP"), "NP")) -> NP | I5: =IF(AND(A5 >= 'Task - Upliftment'!$E$3, A5 <= 'Task - Upliftment'!$F$3, OR(B5="Instagram", B5="YouTube")), "Present", IF(A5 < 'Task - Upliftment'!$E$3, IF(OR(B5="Instagram", B5="YouTube"), "Before", "NP"), "NP")) -> Before | J5: =IF(AND(A5 >= 'Task - Upliftment'!$E$4, A5 <= 'Task - Upliftment'!$F$4, OR(B5="Facebook", B5="Twitter")), "Present", IF(A5 < 'Task - Upliftment'!$E$4, IF(OR(B5="Facebook", B5="Twitter"), "Before", "NP"), "NP")) -> NP | K5: =IF(AND(A5 >= 'Task - Upliftment'!$E$5, A5 <= 'Task - Upliftment'!$F$5, OR(B5="Instagram", B5="Twitter")), "Present", IF(A5 < 'Task - Upliftment'!$E$5, IF(OR(B5="Instagram", B5="Twitter"), "Before", "NP"), "NP")) -> NP
A6: 2024-06-10 | B6: Instagram | C6: 656 | D6: 139 | E6: 49157 | F6: 9.05 | G6: 9920 | H6: =IF(AND(A6 >= 'Task - Upliftment'!$E$2, A6 <= 'Task - Upliftment'!$F$2, OR(B6="Instagram", B6="Facebook")), "Present", IF(A6 < 'Task - Upliftment'!$E$2, IF(OR(B6="Instagram", B6="Facebook"), "Before", "NP"), "NP")) -> Before | I6: =IF(AND(A6 >= 'Task - Upliftment'!$E$3, A6 <= 'Task - Upliftment'!$F$3, OR(B6="Instagram", B6="YouTube")), "Present", IF(A6 < 'Task - Upliftment'!$E$3, IF(OR(B6="Instagram", B6="YouTube"), "Before", "NP"), "NP")) -> Before | J6: =IF(AND(A6 >= 'Task - Upliftment'!$E$4, A6 <= 'Task - Upliftment'!$F$4, OR(B6="Facebook", B6="Twitter")), "Present", IF(A6 < 'Task - Upliftment'!$E$4, IF(OR(B6="Facebook", B6="Twitter"), "Before", "NP"), "NP")) -> NP | K6: =IF(AND(A6 >= 'Task - Upliftment'!$E$5, A6 <= 'Task - Upliftment'!$F$5, OR(B6="Instagram", B6="Twitter")), "Present", IF(A6 < 'Task - Upliftment'!$E$5, IF(OR(B6="Instagram", B6="Twitter"), "Before", "NP"), "NP")) -> Before
A7: 2024-06-10 | B7: Facebook | C7: 1697 | D7: 414 | E7: 316555 | F7: 2.37 | G7: 7924 | H7: =IF(AND(A7 >= 'Task - Upliftment'!$E$2, A7 <= 'Task - Upliftment'!$F$2, OR(B7="Instagram", B7="Facebook")), "Present", IF(A7 < 'Task - Upliftment'!$E$2, IF(OR(B7="Instagram", B7="Facebook"), "Before", "NP"), "NP")) -> Before | I7: =IF(AND(A7 >= 'Task - Upliftment'!$E$3, A7 <= 'Task - Upliftment'!$F$3, OR(B7="Instagram", B7="YouTube")), "Present", IF(A7 < 'Task - Upliftment'!$E$3, IF(OR(B7="Instagram", B7="YouTube"), "Before", "NP"), "NP")) -> NP | J7: =IF(AND(A7 >= 'Task - Upliftment'!$E$4, A7 <= 'Task - Upliftment'!$F$4, OR(B7="Facebook", B7="Twitter")), "Present", IF(A7 < 'Task - Upliftment'!$E$4, IF(OR(B7="Facebook", B7="Twitter"), "Before", "NP"), "NP")) -> Before | K7: =IF(AND(A7 >= 'Task - Upliftment'!$E$5, A7 <= 'Task - Upliftment'!$F$5, OR(B7="Instagram", B7="Twitter")), "Present", IF(A7 < 'Task - Upliftment'!$E$5, IF(OR(B7="Instagram", B7="Twitter"), "Before", "NP"), "NP")) -> NP
A8: 2024-06-10 | B8: Twitter | C8: 436 | D8: 250 | E8: 254347 | F8: 4.01 | G8: 8912 | H8: =IF(AND(A8 >= 'Task - Upliftment'!$E$2, A8 <= 'Task - Upliftment'!$F$2, OR(B8="Instagram", B8="Facebook")), "Present", IF(A8 < 'Task - Upliftment'!$E$2, IF(OR(B8="Instagram", B8="Facebook"), "Before", "NP"), "NP")) -> NP | I8: =IF(AND(A8 >= 'Task - Upliftment'!$E$3, A8 <= 'Task - Upliftment'!$F$3, OR(B8="Instagram", B8="YouTube")), "Present", IF(A8 < 'Task - Upliftment'!$E$3, IF(OR(B8="Instagram", B8="YouTube"), "Before", "NP"), "NP")) -> NP | J8: =IF(AND(A8 >= 'Task - Upliftment'!$E$4, A8 <= 'Task - Upliftment'!$F$4, OR(B8="Facebook", B8="Twitter")), "Present", IF(A8 < 'Task - Upliftment'!$E$4, IF(OR(B8="Facebook", B8="Twitter"), "Before", "NP"), "NP")) -> Before | K8: =IF(AND(A8 >= 'Task - Upliftment'!$E$5, A8 <= 'Task - Upliftment'!$F$5, OR(B8="Instagram", B8="Twitter")), "Present", IF(A8 < 'Task - Upliftment'!$E$5, IF(OR(B8="Instagram", B8="Twitter"), "Before", "NP"), "NP")) -> Before
A9: 2024-06-10 | B9: YouTube | C9: 1197 | D9: 203 | E9: 413878 | F9: 3.16 | G9: 21205 | H9: =IF(AND(A9 >= 'Task - Upliftment'!$E$2, A9 <= 'Task - Upliftment'!$F$2, OR(B9="Instagram", B9="Facebook")), "Present", IF(A9 < 'Task - Upliftment'!$E$2, IF(OR(B9="Instagram", B9="Facebook"), "Before", "NP"), "NP")) -> NP | I9: =IF(AND(A9 >= 'Task - Upliftment'!$E$3, A9 <= 'Task - Upliftment'!$F$3, OR(B9="Instagram", B9="YouTube")), "Present", IF(A9 < 'Task - Upliftment'!$E$3, IF(OR(B9="Instagram", B9="YouTube"), "Before", "NP"), "NP")) -> Before | J9: =IF(AND(A9 >= 'Task - Upliftment'!$E$4, A9 <= 'Task - Upliftment'!$F$4, OR(B9="Facebook", B9="Twitter")), "Present", IF(A9 < 'Task - Upliftment'!$E$4, IF(OR(B9="Facebook", B9="Twitter"), "Before", "NP"), "NP")) -> NP | K9: =IF(AND(A9 >= 'Task - Upliftment'!$E$5, A9 <= 'Task - Upliftment'!$F$5, OR(B9="Instagram", B9="Twitter")), "Present", IF(A9 < 'Task - Upliftment'!$E$5, IF(OR(B9="Instagram", B9="Twitter"), "Before", "NP"), "NP")) -> NP
A10: 2024-06-17 | B10: Instagram | C10: 1048 | D10: 155 | E10: 456946 | F10: 2.46 | G10: 11329 | H10: =IF(AND(A10 >= 'Task - Upliftment'!$E$2, A10 <= 'Task - Upliftment'!$F$2, OR(B10="Instagram", B10="Facebook")), "Present", IF(A10 < 'Task - Upliftment'!$E$2, IF(OR(B10="Instagram", B10="Facebook"), "Before", "NP"), "NP")) -> Present | I10: =IF(AND(A10 >= 'Task - Upliftment'!$E$3, A10 <= 'Task - Upliftment'!$F$3, OR(B10="Instagram", B10="YouTube")), "Present", IF(A10 < 'Task - Upliftment'!$E$3, IF(OR(B10="Instagram", B10="YouTube"), "Before", "NP"), "NP")) -> Before | J10: =IF(AND(A10 >= 'Task - Upliftment'!$E$4, A10 <= 'Task - Upliftment'!$F$4, OR(B10="Facebook", B10="Twitter")), "Present", IF(A10 < 'Task - Upliftment'!$E$4, IF(OR(B10="Facebook", B10="Twitter"), "Before", "NP"), "NP")) -> NP | K10: =IF(AND(A10 >= 'Task - Upliftment'!$E$5, A10 <= 'Task - Upliftment'!$F$5, OR(B10="Instagram", B10="Twitter")), "Present", IF(A10 < 'Task - Upliftment'!$E$5, IF(OR(B10="Instagram", B10="Twitter"), "Before", "NP"), "NP")) -> Before
A11: 2024-06-17 | B11: Facebook | C11: 1753 | D11: 371 | E11: 169496 | F11: 8.11 | G11: 46670 | H11: =IF(AND(A11 >= 'Task - Upliftment'!$E$2, A11 <= 'Task - Upliftment'!$F$2, OR(B11="Instagram", B11="Facebook")), "Present", IF(A11 < 'Task - Upliftment'!$E$2, IF(OR(B11="Instagram", B11="Facebook"), "Before", "NP"), "NP")) -> Present | I11: =IF(AND(A11 >= 'Task - Upliftment'!$E$3, A11 <= 'Task - Upliftment'!$F$3, OR(B11="Instagram", B11="YouTube")), "Present", IF(A11 < 'Task - Upliftment'!$E$3, IF(OR(B11="Instagram", B11="YouTube"), "Before", "NP"), "NP")) -> NP | J11: =IF(AND(A11 >= 'Task - Upliftment'!$E$4, A11 <= 'Task - Upliftment'!$F$4, OR(B11="Facebook", B11="Twitter")), "Present", IF(A11 < 'Task - Upliftment'!$E$4, IF(OR(B11="Facebook", B11="Twitter"), "Before", "NP"), "NP")) -> Before | K11: =IF(AND(A11 >= 'Task - Upliftment'!$E$5, A11 <= 'Task - Upliftment'!$F$5, OR(B11="Instagram", B11="Twitter")), "Present", IF(A11 < 'Task - Upliftment'!$E$5, IF(OR(B11="Instagram", B11="Twitter"), "Before", "NP"), "NP")) -> NP
A12: 2024-06-17 | B12: Twitter | C12: 1335 | D12: 40 | E12: 122732 | F12: 8.19 | G12: 22482 | H12: =IF(AND(A12 >= 'Task - Upliftment'!$E$2, A12 <= 'Task - Upliftment'!$F$2, OR(B12="Instagram", B12="Facebook")), "Present", IF(A12 < 'Task - Upliftment'!$E$2, IF(OR(B12="Instagram", B12="Facebook"), "Before", "NP"), "NP")) -> NP | I12: =IF(AND(A12 >= 'Task - Upliftment'!$E$3, A12 <= 'Task - Upliftment'!$F$3, OR(B12="Instagram", B12="YouTube")), "Present", IF(A12 < 'Task - Upliftment'!$E$3, IF(OR(B12="Instagram", B12="YouTube"), "Before", "NP"), "NP")) -> NP | J12: =IF(AND(A12 >= 'Task - Upliftment'!$E$4, A12 <= 'Task - Upliftment'!$F$4, OR(B12="Facebook", B12="Twitter")), "Present", IF(A12 < 'Task - Upliftment'!$E$4, IF(OR(B12="Facebook", B12="Twitter"), "Before", "NP"), "NP")) -> Before | K12: =IF(AND(A12 >= 'Task - Upliftment'!$E$5, A12 <= 'Task - Upliftment'!$F$5, OR(B12="Instagram", B12="Twitter")), "Present", IF(A12 < 'Task - Upliftment'!$E$5, IF(OR(B12="Instagram", B12="Twitter"), "Before", "NP"), "NP")) -> Before
A13: 2024-06-17 | B13: YouTube | C13: 403 | D13: 66 | E13: 382851 | F13: 3.49 | G13: 24313 | H13: =IF(AND(A13 >= 'Task - Upliftment'!$E$2, A13 <= 'Task - Upliftment'!$F$2, OR(B13="Instagram", B13="Facebook")), "Present", IF(A13 < 'Task - Upliftment'!$E$2, IF(OR(B13="Instagram", B13="Facebook"), "Before", "NP"), "NP")) -> NP | I13: =IF(AND(A13 >= 'Task - Upliftment'!$E$3, A13 <= 'Task - Upliftment'!$F$3, OR(B13="Instagram", B13="YouTube")), "Present", IF(A13 < 'Task - Upliftment'!$E$3, IF(OR(B13="Instagram", B13="YouTube"), "Before", "NP"), "NP")) -> Before | J13: =IF(AND(A13 >= 'Task - Upliftment'!$E$4, A13 <= 'Task - Upliftment'!$F$4, OR(B13="Facebook", B13="Twitter")), "Present", IF(A13 < 'Task - Upliftment'!$E$4, IF(OR(B13="Facebook", B13="Twitter"), "Before", "NP"), "NP")) -> NP | K13: =IF(AND(A13 >= 'Task - Upliftment'!$E$5, A13 <= 'Task - Upliftment'!$F$5, OR(B13="Instagram", B13="Twitter")), "Present", IF(A13 < 'Task - Upliftment'!$E$5, IF(OR(B13="Instagram", B13="Twitter"), "Before", "NP"), "NP")) -> NP
... A201: 2025-05-12 | B201: YouTube | C201: 119 | D201: 456 | E201: 82558 | F201: 6.81 | G201: 12174 | H201: =IF(AND(A201 >= 'Task - Upliftment'!$E$2, A201 <= 'Task - Upliftment'!$F$2, OR(B201="Instagram", B201="Facebook")), "Present", IF(A201 < 'Task - Upliftment'!$E$2, IF(OR(B201="Instagram", B201="Facebook"), "Before", "NP"), "NP")) -> NP | I201: =IF(AND(A201 >= 'Task - Upliftment'!$E$3, A201 <= 'Task - Upliftment'!$F$3, OR(B201="Instagram", B201="YouTube")), "Present", IF(A201 < 'Task - Upliftment'!$E$3, IF(OR(B201="Instagram", B201="YouTube"), "Before", "NP"), "NP")) -> NP | J201: =IF(AND(A201 >= 'Task - Upliftment'!$E$4, A201 <= 'Task - Upliftment'!$F$4, OR(B201="Facebook", B201="Twitter")), "Present", IF(A201 < 'Task - Upliftment'!$E$4, IF(OR(B201="Facebook", B201="Twitter"), "Before", "NP"), "NP")) -> NP | K201: =IF(AND(A201 >= 'Task - Upliftment'!$E$5, A201 <= 'Task - Upliftment'!$F$5, OR(B201="Instagram", B201="Twitter")), "Present", IF(A201 < 'Task - Upliftment'!$E$5, IF(OR(B201="Instagram", B201="Twitter"), "Before", "NP"), "NP")) -> NP

Sheet Task 5.1.1
A1: Campaign Name | B1: Average Likes | C1: Average Impression | D1: Average Clicks
A2: SummerSplash | B2: =AVERAGEIF('Data Used -1'!M:M,A2,'Data Used -1'!F:F) -> 2891.5208 | C2: =AVERAGEIF('Data Used -1'!M:M,A2,'Data Used -1'!I:I) -> 38464 | D2: =AVERAGEIF('Data Used -1'!M:M,A2,'Data Used -1'!K:K) -> 134.04167
A3: FestiveRadiance | B3: =AVERAGEIF('Data Used -1'!M:M,A3,'Data Used -1'!F:F) -> 2754.8793 | C3: =AVERAGEIF('Data Used -1'!M:M,A3,'Data Used -1'!I:I) -> 34247.517 | D3: =AVERAGEIF('Data Used -1'!M:M,A3,'Data Used -1'!K:K) -> 170.2069
A4: NewYearRefresh | B4: =AVERAGEIF('Data Used -1'!M:M,A4,'Data Used -1'!F:F) -> 2736.5075 | C4: =AVERAGEIF('Data Used -1'!M:M,A4,'Data Used -1'!I:I) -> 33821.687 | D4: =AVERAGEIF('Data Used -1'!M:M,A4,'Data Used -1'!K:K) -> 149.73134
A5: DailyWellness | B5: =AVERAGEIF('Data Used -1'!M:M,A5,'Data Used -1'!F:F) -> 2646.6056 | C5: =AVERAGEIF('Data Used -1'!M:M,A5,'Data Used -1'!I:I) -> 34716.394 | D5: =AVERAGEIF('Data Used -1'!M:M,A5,'Data Used -1'!K:K) -> 150.5493
A8: Campaign Name | B8: Sum Likes | C8: Sum Impression | D8: Sum Clicks
A9: SummerSplash | B9: =SUMIF('Data Used -1'!M:M,Sum[[#This Row],[Campaign Name]],'Data Used -1'!F:F) -> 138793 | C9: =SUMIF('Data Used -1'!M:M,A9,'Data Used -1'!I:I) -> 1846272 | D9: =SUMIF('Data Used -1'!M:M,A9,'Data Used -1'!K:K) -> 6434
A10: FestiveRadiance | B10: =SUMIF('Data Used -1'!M:M,A3,'Data Used -1'!F:F) -> 159783 | C10: =SUMIF('Data Used -1'!M:M,A10,'Data Used -1'!I:I) -> 1986356 | D10: =SUMIF('Data Used -1'!M:M,A10,'Data Used -1'!K:K) -> 9872
A11: NewYearRefresh | B11: =SUMIF('Data Used -1'!M:M,A4,'Data Used -1'!F:F) -> 183346 | C11: =SUMIF('Data Used -1'!M:M,A11,'Data Used -1'!I:I) -> 2266053 | D11: =SUMIF('Data Used -1'!M:M,A11,'Data Used -1'!K:K) -> 10032
A12: DailyWellness | B12: =SUMIF('Data Used -1'!M:M,A5,'Data Used -1'!F:F) -> 187909 | C12: =SUMIF('Data Used -1'!M:M,A12,'Data Used -1'!I:I) -> 2464864 | D12: =SUMIF('Data Used -1'!M:M,A12,'Data Used -1'!K:K) -> 10689

Sheet Task - Upliftment
A1: Campaign_Name | B1: Engagement During Campain Period | C1: Engagement Before Campain Period | D1: Engagement Uplift | E1: Start_Date | F1: End_Date
A2: SummerSplash | B2: =AVERAGEIF('Data Used - 3'!H:H,"Present",'Data Used - 3'!F:F) -> 6.128 | C2: =AVERAGEIF('Data Used - 3'!H:H,"Before",'Data Used - 3'!F:F) -> 6.115 | D2: =(B2-C2)/C2 -> 0.0021259199 | E2: 2024-06-15 | F2: 2024-07-15
A3: FestiveRadiance | B3: =AVERAGEIF('Data Used - 3'!I:I,"Present",'Data Used - 3'!F:F) -> 5.71625 | C3: =+AVERAGEIF('Data Used - 3'!I:I,"Before",'Data Used - 3'!F:F) -> 5.6236111 | D3: =(B3-C3)/C3 -> 0.016473203 | E3: 2024-10-01 | F3: 2024-10-31
A4: NewYearRefresh | B4: =AVERAGEIF('Data Used - 3'!J:J,"Present",'Data Used - 3'!F:F) -> 4.5475 | C4: =+AVERAGEIF('Data Used - 3'!J:J,"Before",'Data Used - 3'!F:F) -> 5.8706667 | D4: =(B4-C4)/C4 -> -0.2253861 | E4: 2024-12-25 | F4: 2025-01-10
A5: DailyWellness | B5: =AVERAGEIF('Data Used - 3'!K:K,"Present",'Data Used - 3'!F:F) -> 5.967 | C5: =AVERAGEIF('Data Used - 3'!K:K,"Before",'Data Used - 3'!F:F) -> 5.795641 | D5: =(B5-C5)/C5 -> 0.029566872 | E5: 2025-03-01 | F5: 2025-03-31

Sheet Task - ROI
A1: Campaign_Name | B1: Campaign_Budget | C1: Avg_Enagaement | D1: ROI
A2: SummerSplash | B2: 150000 | C2: =AVERAGEIF('Data Used - 3'!H:H,"Present",'Data Used - 3'!$F:$F) -> 6.128 | D2: =C2/B2*100 -> 0.0040853333
A3: FestiveRadiance | B3: 200000 | C3: =AVERAGEIF('Data Used - 3'!I:I,"Present",'Data Used - 3'!$F:$F) -> 5.71625 | D3: =C3/B3*100 -> 0.002858125
A4: NewYearRefresh | B4: 250000 | C4: =AVERAGEIF('Data Used - 3'!J:J,"Present",'Data Used - 3'!$F:$F) -> 4.5475 | D4: =C4/B4*100 -> 0.001819
A5: DailyWellness | B5: 180000 | C5: =AVERAGEIF('Data Used - 3'!K:K,"Present",'Data Used - 3'!$F:$F) -> 5.967 | D5: =C5/B5*100 -> 0.003315

Sheet Followers Growth
A1: Campaign_Name | B1: Total Followers Before campaign start | C1: Total New Followers | D1: Total Unfollows | E1: Growt_Rate | F1: Start_Date | G1: End_Date
A2: SummerSplash | B2: =SUMIF('Data Used - 3'!H:H,"Before",'Data Used - 3'!E:E) -> 752450 | C2: =SUMIF('Data Used - 3'!H:H,"Present",'Data Used - 3'!C:C) -> 10459 | D2: =SUMIF('Data Used - 3'!H:H,"Present",'Data Used - 3'!D:D) -> 2378 | E2: =((C2-D2)/B2) -> 0.010739584 | F2: 2024-06-15 | G2: 2024-07-15
A3: FestiveRadiance | B3: =SUMIF('Data Used - 3'!I:I,"Before",'Data Used - 3'!E:E) -> 8998409 | C3: =SUMIF('Data Used - 3'!I:I,"Present",'Data Used - 3'!C:C) -> 9053 | D3: =SUMIF('Data Used - 3'!I:I,"Present",'Data Used - 3'!D:D) -> 1493 | E3: =((C3-D3)/B3) -> 0.00084014852 | F3: 2024-10-01 | G3: 2024-10-31
A4: NewYearRefresh | B4: =SUMIF('Data Used - 3'!J:J,"Before",'Data Used - 3'!E:E) -> 16253254 | C4: =SUMIF('Data Used - 3'!J:J,"Present",'Data Used - 3'!C:C) -> 6215 | D4: =SUMIF('Data Used - 3'!J:J,"Present",'Data Used - 3'!D:D) -> 1102 | E4: =((C4-D4)/B4) -> 0.00031458316 | F4: 2024-12-25 | G4: 2025-01-10
A5: DailyWellness | B5: =SUMIF('Data Used - 3'!K:K,"Before",'Data Used - 3'!E:E) -> 21395555 | C5: =SUMIF('Data Used - 3'!K:K,"Present",'Data Used - 3'!C:C) -> 10121 | D5: =SUMIF('Data Used - 3'!K:K,"Present",'Data Used - 3'!D:D) -> 1734 | E5: =((C5-D5)/B5) -> 0.00039199731 | F5: 2025-03-01 | G5: 2025-03-31
